Workbook
Name riskTypes: [1]Validation!$G$13:$G$16

Sheet INTRO
B2: CLIMATE IMPACT ASSESSMENT TOOL
C4: This is the Climate Impact Assessment (CIA) Tool. It has been designed to support compliance with the Climate Change Act 2021, specifically the climate change duties for public bodies, which are:
C6: (1) A public body, in performing its duties, must act in the way that it considers best to contribute to —
C7: (a) | D7: the meeting of the net zero emissions target by the net zero emissions target year;
C8: (b) | D8: the meeting of any interim target;
C9: (c) | D9: supporting the just transition principles and the climate justice principle;
C10: (d) | D10: sustainable development, including the achievement of the United Nations sustainable development goals; and
C11: (e) | D11: protecting and enhancing biodiversity, ecosystems and ecosystem services.
C13: To find out more about any of the climate change duties for public bodies, please visit www.netzero.im/publicbodies
C15: In certain circumstances, completing a CIA is a legal requirement. To find out whether you must complete a CIA, first complete the 'CIA-Screening' tab.
C17: You may complete a CIA for any proposal, if you think that it would be useful.
C19: The CIA should be completed in a group.
C21: The CIA User Guide can be found here.
C23: The CIA Tool itself also contains guidance - hover over any field with a red triangle in the corner to access guidance. If you have any problems viewing the guidance in the red triangles, the full text is provided on the 'Guidance' tab.
C25: The guidance also provides contact details for specialist teams around government would will be able to help you if you are not sure about the impacts in a certain area.
C27: If you are still not sure after accessing the in-tool guidance and the User Guide, please contact publicbodiesclimate@gov.im
C29: Once you have completed the CIA, it should be reviewed by your manager (or whoever is reviewing the package of papers relating to your proposal before submission to the decision maker).
C31: Once all criteria have been marked accepted by the Reviewer, the CIA can be submitted to the Decision Maker. To do this, print the Summary Report page as a pdf and include it with the rest of the documents relating to your proposal.
C32: Supporting our Biosphere The CIA has been designed to help public bodies assess their proposals and activities for compliance with their climate change duties (see Legal Obligations in the User Guide). Beyond climate, it recognises all important considerations as a Biosphere Reserve. The Man and the Biosphere Programme, aims to establish a scientific basis for enhancing the relationship between people and their environments and supports the United Nations’ Sustainable Development Goals. As a whole nation Biosphere, Isle of Man public bodies can use the CIA as an aid to develop in a way which is sustainable for people and the rest of nature, finding balanced but innovative solutions collectively.

Sheet Details
C2: PROPOSAL DETAILS
C3: Title (What is being assessed?)
C6: What type of proposal is being assessed? (choose from drop down)
C9: Enter a brief description of the proposal:
C12: Name of Department/public body
C15: Name of section/division/team/directorate (as applicable)
C17: Who completed this assessment?
C18: Enter the name of the lead/contact person:
C20: It is recommended that the CIA be completed in a group. Please enter the names of anyone else who contributed to completing the assessment below:
C23: Date assessment completed:
C26: Aims, objectives, anticipated outcomes of proposal:
C29: List those responsible for implementing/delivering the proposal:
B32: Please proceed to CIA-Screening

Sheet CIA-Screening
C2: Climate Impact Assessment - Screening
C3: Complete the following questions to find out if a Climate Impact Assessment is required:
C4: EXCEPTIONS
C5: Do any of the following describe your proposal? | E5: Select from drop down
C6: Implementation of the proposal without delay is necessary to protect life or national security.
C7: Implementation of the proposal without delay is necessary for the safeguarding or protection of children or vulnerable adults.
C8: The proposal is made under section 23 of the Custody Act 1995 (Early release of detainees)
C9: The proposal is for a change/s to delegation/s, staff recruitment or remuneration.
C10: The proposal is for immaterial amendments to a document (e.g.. corrections, formatting etc.)
C11: The proposal is one that is being repeated exactly within 12 months of the initial climate impact assessment having been completed
C12: The proposal is for a feasibility study and the climate change duties are incorporated into the feasibility criteria.
C14: RESULT: | D14: =FORMULAS!D3 -> EXCEPTIONS SECTION INCOMPLETE
D15: If 'No CIA required' do not complete the questions below.
C16: THRESHOLDS
C17: Does your proposal… | E17: Select from drop down
C18: Require approval by a member of Tynwald in a decision making capacity for the public body
C19: Require approval by a board, committee or other decision making group that includes member of Tynwald in a decision making capacity for the public body
C20: Require or create changes to — (i) spending; (ii) allocation of funding; or (iii) annual revenue; amounting to at least £100,000;
C21: Has the person or body responsible for approving your proposal requested a Climate Impact Assessment?
C23: RESULT: | D23: =FORMULAS!D5 -> THRESHOLDS SECTION INCOMPLETE
C24: If your screening returns a result of NO CIA REQUIRED you do not need to complete the 'CIA-Environment' or 'CIA-Social' sections of this tool.
C25: DISCRETION
C26: Regulation 5(1)(c) allows a public body not to prepare a Climate Impact Assessment, even where one or more of the above thresholds are met, where that public body considers the proposal has no relevance to, or impact on, the compliance by the public body with section 21 (climate change duties of public bodies) of the Act.
C27: If you choose to exercise this discretion you MUST explain why:

Sheet CIA-Environment
B2: Climate Impact Assessment
B3: INTRODUCTION
C5: The Climate Impact Assessment helps to ensure that the decisions of public bodies align with the climate change duties for public bodies (section 21 of the Climate Change Act 2021), as follows:
C6: (1) A public body, in performing its duties, must act in the way that it considers best to contribute to —
C7: (a) | D7: the meeting of the net zero emissions target by the net zero emissions target year;
C8: (b) | D8: the meeting of any interim target;
C9: (c) | D9: supporting the just transition principles and the climate justice principle;
C10: (d) | D10: sustainable development, including the achievement of the United Nations sustainable
D11: development goals; and
C12: (e) | D12: protecting and enhancing biodiversity, ecosystems and ecosystem services. | N12: If you have a question that is not covered by the in-tool guidance - please refer to the User Guide available at https://www.netzero.im/resources/public-bodies/cia/
G14: In each section you will find icons indicating the relevant UN Sustainable Development Goal (SDG)
G15: For more information on the SDGs, click here.
C17: Completing the CIA:
C19: For more detailed guidance on how to complete the CIA, please visit the User Guide. To arrange training please contact publicbodiesclimate@gov.im
C21: If you choose 'Not applicable/No impact' in question a. of any section, then questions b. and c. will appear hatched grey and you do not need to answer them.
C23: Question b. in each section asks about 'impacts beyond the delivery phase' - the 'delivery phase' means the actions necessary for setting up/putting in place rather than the ongoing implementation/running of the project or policy.
C25: Question c. in each section asks about the impacts beyond the 'intended location' - if your proposal relates to a specific area of the Island, e.g.. a town, then that is the 'intended location'. If your proposal is intended to affect the whole Island, e.g.. a new piece of legislation, then the answer to this question will likely be 'No'. If you are not sure please contact publicbodiesclimate@gov.im
C27: Question d. asks you to explain your answers and provides a free text field for you to explain your mitigations and justifications. This helps with the review process and provides a track record as the project develops. It is recommended that you add a justification even if you have indicated there is no impact, as this will show the reviewer/decision makers how you came to that conclusion.
C28: If you need more space to answer any of the questions, please increase the row size by highlighting the row and dragging it larger using the left hand bar. Please do not adjust the column width.
B29: PART 1: ENVIRONMENTAL IMPACTS | H29: Please answer all sections | L29: HIDDEN
B30: 1. Greenhouse Gases (GHGs) | H30: Note: If you have any problems with viewing the guidance by hovering over the red triangles, you can access the same text, in full on the 'Guidance' tab.
B31: How will this proposal impact levels of GHG emissions and/or removals? Consider: • Fossil fuels used to heat homes or drive vehicles • Methane released by livestock or waste processes • Fertilisers or agricultural activities • Industrial refrigeration and air-conditioning processes • Increasing 'removals' - the capture and storage of CO2, sometimes known as 'sequestration' - typically achieved through habitat creation or restoration. | L31: Scores
C32: Why does this matter? | E32: Not sure? | G32: Get more help
B34: a. | C34: Please specify the impact your proposal will have on GHGs:
L35: =IF(C35="Significantly reduce GHG emissions (or significantly increase removals)",2, IF(C35="Slightly reduce GHG emissions (or slightly increase removals)",1, IF(C35="not applicable/no impact",0, IF(C35="Slightly increase GHG emissions (or slightly reduce removals)", -1, IF(C35="Significantly increase GHG emissions (or signficiantly reduce removals)", -2, IF(C35="",20,"")))))) -> 20
B37: b. | C37: Will this impact last beyond the delivery phase?
L38: =IF(C38="yes",2,IF(C38="no",1,"0")) -> 0
B40: c. | C40: Will this have an impact beyond the intended delivery location?
L41: =IF(C41="yes",2,IF(C41="no",1,"0")) -> 0
L42: =IF(C35="",20,((L35*L38)*L41)) -> 20
B43: d. | C43: Explain why you chose these options including any mitigations or justifications:
L44: =IF(C44="",0,1) -> 0
B47: 2. Air Quality
B48: How will this proposal impact the level of pollutants in the air? Consider: • Outdoor air pollution (e.g. exhaust fumes, particles from brake/tyre erosion, burning fuels, industrial activity) • Indoor air quality (e.g. mould, damp, gases/chemicals from building materials, cooking emissions, fuel use)
C49: Why does this matter? | E49: Not sure? | G49: Get more help
B51: a. | C51: Please specify the impact your proposal will have on air pollution:
L52: =IF(C52="significantly decrease air pollutants",2, IF(C52="slightly decrease air pollutants",1, IF(C52="not applicable/no impact",0, IF(C52="slightly increase air pollutants", -1, IF(C52="significantly increase air pollutants", -2, IF(C52="",20,"")))))) -> 20
B54: b. | C54: Will this impact last beyond the delivery phase?
L55: =IF(C55="yes",2,IF(C55="no",1,"0")) -> 0
B57: c. | C57: Will this impact air quality beyond the intended delivery location?
...

Sheet CIA-Social
B2: Climate Impact Assessment
B3: PART 2: SOCIAL IMPACTS | H3: Please answer all sections | L3: HIDDEN
B4: 1. Food | U4: Opportunities
C5: How will this proposal support access to healthy and affordable food? Consider: • food security/access • physical access (e.g. distances/routes to places people get food, types of foods available, supply chains) • financial access (i.e. whether food is affordable to people) | L5: Scores | U5: Allotments | V5: FALSE | W5: =IF(#REF!=TRUE,"Consider for the access and equity question: is the cost prohibitive for most? Are they in accessible locations? Do you need a car to get there?","") -> #REF!
C6: Why is this important? | E6: Not sure? | G6: More help | U6: Food bank | V6: FALSE
U7: Parcels | V7: FALSE
B8: a. Please specify the impact your project will have on food: | U8: Closure | V8: FALSE
L9: =IF(C9="significantly promote healthy and/or affordable food",2, IF(C9="slightly promote healthy and/or affordable food",1, IF(C9="not applicable/no impact",0, IF(C9="slightly impede healthy and/or affordable food", -1, IF(C9="significantly impede healthy and/or affordable food", -2, IF(C9="",20,"")))))) -> 20 | U9: Ads | V9: FALSE
U10: Classes | V10: FALSE
B11: b. Will this impact last beyond the delivery phase of the project? | U11: Price | V11: FALSE
L12: =IF(C12="yes",2,IF(C12="no",1,"0")) -> 0 | U12: Menus | V12: FALSE
U13: Campaign | V13: FALSE
B14: c. Will there be an impact on food beyond the delivery location of the project? | U14: Community | V14: FALSE
L15: =IF(C15="yes",2,IF(C15="no",1,"0")) -> 0 | U15: Fast food | V15: FALSE
L16: =IF(C9="",20,((L9*L12)*L15)) -> 20 | U16: Supermarket | V16: FALSE
B17: d. | C17: Explain why you chose these options including any mitigations or justifications:
L18: =IF(C18="",1,0) -> 1
B21: 2. Health & Wellbeing
C22: How will this proposal support people to live a healthy life and benefit physical and mental health? Consider: • access to physical and mental health services (eg. doctors, specialists, addiction support, counselling) • access to activies that supports physical and mental health (e.g. exercise, time in nature) • access to trustworthy information that supports physical and mental health • service that improve/respond to health and wellbeing risks from the impacts of climate change
C23: Why is this important? | E23: Not sure? | G23: More help
B25: a. Please specify the impact your project will have on health:
L26: =IF(C26="significantly increase positive health outcomes",2, IF(C26="slightly increase positive health outcomes",1, IF(C26="not applicable/no impact",0, IF(C26="slightly decrease positive health outcomes", -1, IF(C26="significantly decrease positive health outcomes", -2, IF(C26="",20,"")))))) -> 20
B28: b. Will this impact last beyond the delivery phase of the project?
L29: =IF(C29="yes",2,IF(C29="no",1,"0")) -> 0
B31: c. Will this impact on health and wellbeing beyond the delivery location?
L32: =IF(C32="yes",2,IF(C32="no",1,"0")) -> 0
L33: =IF(C26="",20,((L26*L29)*L32)) -> 20
B34: d. | C34: Explain why you chose these options including any mitigations or justifications:
L35: =IF(C35="",1,0) -> 1
B38: 3. Housing
C39: How will this proposal impact availability of and access to quality housing and affordable homes? Consider: • Poor housing issues (e.g. damp, cold, mould, overcrowding, needing repairs, high energy use) • Indirect impacts (e.g. housing affordability and prices) • Support for those who are homeless or at risk of homelessness • Ensuring housing is fit for a net zero future (e.g. low carbon heating, energy efficiency)
C40: Why is this important? | E40: Not sure? | G40: More help
B42: a. Please specify the impact your project will have on housing:
L43: =IF(C43="Significantly increase the number of or access to quality and/or affordable homes",2, IF(C43="Slightly increase the number of or access to quality and/or affordable homes",1, IF(C43="not applicable/no impact",0, IF(C43="Slightly decrease the number of or access to quality and/or affordable homes", -1, IF(C43="Significantly decrease the number of or access to quality and/or affordable homes", -2, IF(C43="",20,"")))))) -> 20
B45: b. Will this impact last beyond the delivery phase of the project?
L46: =IF(C46="yes",2,IF(C46="no",1,"0")) -> 0
B48: c. Will this impact on quality or affordability of homes beyond the delivery location?
L49: =IF(C49="yes",2,IF(C49="no",1,"0")) -> 0
L50: =IF(C43="",20,((L43*L46)*L49)) -> 20
B51: d. | C51: Explain why you chose these options including any mitigations or justifications:
...

Sheet Env Wheel
A2: GHG | B2: =$J$3 -> 0 | H2: Environmental | I2: Score | J2: green | K2: light green | L2: grey | M2: amber | N2: red | O2: Blank
B3: =$K$3 -> 0 | H3: GHG | I3: ='CIA-Environment'!L42 -> 20 | J3: =IF(AND(I3<20, I3>=4),1,0) -> 0 | K3: =IF(AND(I3>0,I3<=3),1,0) -> 0 | L3: =IF(I3=0,1,0) -> 0 | M3: =IF(AND(I3<0,I3>=-3),1,0) -> 0 | N3: =IF(I3<=-4,1,0) -> 0 | O3: =IF(I3>=20,1,0) -> 1
B4: =$L$3 -> 0 | H4: Air quality | I4: ='CIA-Environment'!L59 -> 20 | J4: =IF(AND(I4<20, I4>=4),1,0) -> 0 | K4: =IF(AND(I4>0,I4<=3),1,0) -> 0 | L4: =IF(I4=0,1,0) -> 0 | M4: =IF(AND(I4<0,I4>=-3),1,0) -> 0 | N4: =IF(I4<=-4,1,0) -> 0 | O4: =IF(I4>=20,1,0) -> 1
B5: =$M$3 -> 0 | H5: Sustainable Transport | I5: ='CIA-Environment'!L76 -> 20 | J5: =IF(AND(I5<20, I5>=4),1,0) -> 0 | K5: =IF(AND(I5>0,I5<=3),1,0) -> 0 | L5: =IF(I5=0,1,0) -> 0 | M5: =IF(AND(I5<0,I5>=-3),1,0) -> 0 | N5: =IF(I5<=-4,1,0) -> 0 | O5: =IF(I5>=20,1,0) -> 1
B6: =$N$3 -> 0 | H6: Land use change | I6: ='CIA-Environment'!L93 -> 20 | J6: =IF(AND(I6<20, I6>=4),1,0) -> 0 | K6: =IF(AND(I6>0,I6<=3),1,0) -> 0 | L6: =IF(I6=0,1,0) -> 0 | M6: =IF(AND(I6<0,I6>=-3),1,0) -> 0 | N6: =IF(I6<=-4,1,0) -> 0 | O6: =IF(I6>=20,1,0) -> 1
B7: =$O$3 -> 1 | H7: Biodiversity | I7: ='CIA-Environment'!L110 -> 20 | J7: =IF(AND(I7<20, I7>=4),1,0) -> 0 | K7: =IF(AND(I7>0,I7<=3),1,0) -> 0 | L7: =IF(I7=0,1,0) -> 0 | M7: =IF(AND(I7<0,I7>=-3),1,0) -> 0 | N7: =IF(I7<=-4,1,0) -> 0 | O7: =IF(I7>=20,1,0) -> 1
A8: air quality | B8: =$J$4 -> 0 | H8: Soil, Waterway and Marine Health | I8: ='CIA-Environment'!L127 -> 20 | J8: =IF(AND(I8<20, I8>=4),1,0) -> 0 | K8: =IF(AND(I8>0,I8<=3),1,0) -> 0 | L8: =IF(I8=0,1,0) -> 0 | M8: =IF(AND(I8<0,I8>=-3),1,0) -> 0 | N8: =IF(I8<=-4,1,0) -> 0 | O8: =IF(I8>=20,1,0) -> 1
B9: =$K$4 -> 0 | H9: Climate change adaptation | I9: ='CIA-Environment'!L144 -> 20 | J9: =IF(AND(I9<20, I9>=4),1,0) -> 0 | K9: =IF(AND(I9>0,I9<=3),1,0) -> 0 | L9: =IF(I9=0,1,0) -> 0 | M9: =IF(AND(I9<0,I9>=-3),1,0) -> 0 | N9: =IF(I9<=-4,1,0) -> 0 | O9: =IF(I9>=20,1,0) -> 1
B10: =$L$4 -> 0 | H10: Energy Use | I10: ='CIA-Environment'!L161 -> 20 | J10: =IF(AND(I10<20, I10>=4),1,0) -> 0 | K10: =IF(AND(I10>0,I10<=3),1,0) -> 0 | L10: =IF(I10=0,1,0) -> 0 | M10: =IF(AND(I10<0,I10>=-3),1,0) -> 0 | N10: =IF(I10<=-4,1,0) -> 0 | O10: =IF(I10>=20,1,0) -> 1
B11: =$M$4 -> 0 | H11: Sustainable Materials | I11: ='CIA-Environment'!L178 -> 20 | J11: =IF(AND(I11<20, I11>=4),1,0) -> 0 | K11: =IF(AND(I11>0,I11<=3),1,0) -> 0 | L11: =IF(I11=0,1,0) -> 0 | M11: =IF(AND(I11<0,I11>=-3),1,0) -> 0 | N11: =IF(I11<=-4,1,0) -> 0 | O11: =IF(I11>=20,1,0) -> 1
B12: =$N$4 -> 0 | H12: Waste | I12: ='CIA-Environment'!L195 -> 20 | J12: =IF(AND(I12<20, I12>=4),1,0) -> 0 | K12: =IF(AND(I12>0,I12<=3),1,0) -> 0 | L12: =IF(I12=0,1,0) -> 0 | M12: =IF(AND(I12<0,I12>=-3),1,0) -> 0 | N12: =IF(I12<=-4,1,0) -> 0 | O12: =IF(I12>=20,1,0) -> 1
B13: =$O$4 -> 1
A14: transport | B14: =$J$5 -> 0
B15: =$K$5 -> 0
B16: =$L$5 -> 0
B17: =$M$5 -> 0
B18: =$N$5 -> 0
B19: =$O$5 -> 1
A20: Land use change | B20: =$J$6 -> 0
B21: =$K$6 -> 0
B22: =$L$6 -> 0
B23: =$M$6 -> 0
B24: =$N$6 -> 0
B25: =$O$6 -> 1
A26: Biodiversity | B26: =$J$7 -> 0
B27: =$K$7 -> 0
B28: =$L$7 -> 0
B29: =$M$7 -> 0
B30: =$N$7 -> 0
B31: =$O$7 -> 1
A32: Soil, Waterway and Marine Health | B32: =$J$8 -> 0
B33: =$K$8 -> 0
B34: =$L$8 -> 0
B35: =$M$8 -> 0
B36: =$N$8 -> 0
B37: =$O$8 -> 1
A38: climate change adaptation | B38: =$J$9 -> 0
B39: =$K$9 -> 0
B40: =$L$9 -> 0
B41: =$M$9 -> 0
...

Sheet Social Wheel
A2: Food | B2: =$J$3 -> 0 | H2: Social | I2: Score | J2: green | K2: light green | L2: grey | M2: amber | N2: red | O2: Blank
B3: =$K$3 -> 0 | H3: Food | I3: ='CIA-Social'!L16 -> 20 | J3: =IF(AND(I3<20,I3>=4),1,0) -> 0 | K3: =IF(AND(I3>0,I3<=3),1,0) -> 0 | L3: =IF(I3=0,1,0) -> 0 | M3: =IF(AND(I3<0,I3>=-3),1,0) -> 0 | N3: =IF(I3<=-4,1,0) -> 0 | O3: =IF(I3>=20,1,0) -> 1
B4: =$L$3 -> 0 | H4: Health and wellbeing | I4: ='CIA-Social'!L33 -> 20 | J4: =IF(AND(I4<20,I4>=4),1,0) -> 0 | K4: =IF(AND(I4>0,I4<=3),1,0) -> 0 | L4: =IF(I4=0,1,0) -> 0 | M4: =IF(AND(I4<0,I4>=-3),1,0) -> 0 | N4: =IF(I4<=-4,1,0) -> 0 | O4: =IF(I4>=20,1,0) -> 1
B5: =$M$3 -> 0 | H5: Housing | I5: ='CIA-Social'!L50 -> 20 | J5: =IF(AND(I5<20,I5>=4),1,0) -> 0 | K5: =IF(AND(I5>0,I5<=3),1,0) -> 0 | L5: =IF(I5=0,1,0) -> 0 | M5: =IF(AND(I5<0,I5>=-3),1,0) -> 0 | N5: =IF(I5<=-4,1,0) -> 0 | O5: =IF(I5>=20,1,0) -> 1
B6: =$N$3 -> 0 | H6: Education | I6: ='CIA-Social'!L67 -> 20 | J6: =IF(AND(I6<20,I6>=4),1,0) -> 0 | K6: =IF(AND(I6>0,I6<=3),1,0) -> 0 | L6: =IF(I6=0,1,0) -> 0 | M6: =IF(AND(I6<0,I6>=-3),1,0) -> 0 | N6: =IF(I6<=-4,1,0) -> 0 | O6: =IF(I6>=20,1,0) -> 1
B7: =$O$3 -> 1 | H7: Built Community | I7: ='CIA-Social'!L84 -> 20 | J7: =IF(AND(I7<20,I7>=4),1,0) -> 0 | K7: =IF(AND(I7>0,I7<=3),1,0) -> 0 | L7: =IF(I7=0,1,0) -> 0 | M7: =IF(AND(I7<0,I7>=-3),1,0) -> 0 | N7: =IF(I7<=-4,1,0) -> 0 | O7: =IF(I7>=20,1,0) -> 1
A8: health | B8: =$J$4 -> 0 | H8: Cultural Community | I8: ='CIA-Social'!L101 -> 20 | J8: =IF(AND(I8<20,I8>=4),1,0) -> 0 | K8: =IF(AND(I8>0,I8<=3),1,0) -> 0 | L8: =IF(I8=0,1,0) -> 0 | M8: =IF(AND(I8<0,I8>=-3),1,0) -> 0 | N8: =IF(I8<=-4,1,0) -> 0 | O8: =IF(I8>=20,1,0) -> 1
B9: =$K$4 -> 0 | H9: Accessibility | I9: ='CIA-Social'!L118 -> 20 | J9: =IF(AND(I9<20,I9>=4),1,0) -> 0 | K9: =IF(AND(I9>0,I9<=3),1,0) -> 0 | L9: =IF(I9=0,1,0) -> 0 | M9: =IF(AND(I9<0,I9>=-3),1,0) -> 0 | N9: =IF(I9<=-4,1,0) -> 0 | O9: =IF(I9>=20,1,0) -> 1
B10: =$L$4 -> 0 | H10: Local Economy and jobs | I10: ='CIA-Social'!L135 -> 20 | J10: =IF(AND(I10<20,I10>=4),1,0) -> 0 | K10: =IF(AND(I10>0,I10<=3),1,0) -> 0 | L10: =IF(I10=0,1,0) -> 0 | M10: =IF(AND(I10<0,I10>=-3),1,0) -> 0 | N10: =IF(I10<=-4,1,0) -> 0 | O10: =IF(I10>=20,1,0) -> 1
B11: =$M$4 -> 0 | H11: Safety | I11: ='CIA-Social'!L152 -> 20 | J11: =IF(AND(I11<20,I11>=4),1,0) -> 0 | K11: =IF(AND(I11>0,I11<=3),1,0) -> 0 | L11: =IF(I11=0,1,0) -> 0 | M11: =IF(AND(I11<0,I11>=-3),1,0) -> 0 | N11: =IF(I11<=-4,1,0) -> 0 | O11: =IF(I11>=20,1,0) -> 1
B12: =$N$4 -> 0 | H12: Democratic voice | I12: ='CIA-Social'!L186 -> 20 | J12: =IF(AND(I12<20,I12>=4),1,0) -> 0 | K12: =IF(AND(I12>0,I12<=3),1,0) -> 0 | L12: =IF(I12=0,1,0) -> 0 | M12: =IF(AND(I12<0,I12>=-3),1,0) -> 0 | N12: =IF(I12<=-4,1,0) -> 0 | O12: =IF(I12>=20,1,0) -> 1
B13: =$O$4 -> 1 | H13: Equity | I13: ='CIA-Social'!L169 -> 20 | J13: =IF(AND(I13<20,I13>=4),1,0) -> 0 | K13: =IF(AND(I13>0,I13<=3),1,0) -> 0 | L13: =IF(I13=0,1,0) -> 0 | M13: =IF(AND(I13<0,I13>=-3),1,0) -> 0 | N13: =IF(I13<=-4,1,0) -> 0 | O13: =IF(I13>=20,1,0) -> 1
A14: housing | B14: =$J$5 -> 0
B15: =$K$5 -> 0
B16: =$L$5 -> 0
B17: =$M$5 -> 0
B18: =$N$5 -> 0
B19: =$O$5 -> 1
A20: education | B20: =$J$6 -> 0
B21: =$K$6 -> 0
B22: =$L$6 -> 0
B23: =$M$6 -> 0
B24: =$N$6 -> 0
B25: =$O$6 -> 1
A26: built | B26: =$J$7 -> 0
B27: =$K$7 -> 0
B28: =$L$7 -> 0
B29: =$M$7 -> 0
B30: =$N$7 -> 0
B31: =$O$7 -> 1
A32: culture | B32: =$J$8 -> 0
B33: =$K$8 -> 0
B34: =$L$8 -> 0
B35: =$M$8 -> 0
B36: =$N$8 -> 0
B37: =$O$8 -> 1
A38: access | B38: =$J$9 -> 0
B39: =$K$9 -> 0
B40: =$L$9 -> 0
B41: =$M$9 -> 0
...

Sheet FORMULAS
A2: CIA | B2: SCREENING | D2: Result - Exceptions table | E2: Result - Summary Report
A3: Exceptions No | B3: =COUNTIF('CIA-Screening'!E6:E12,"No") -> 0 | D3: =IF(B3=7,"NO EXCEPTION/S APPLY - PROCEED TO THRESHOLDS SECTION",IF(B5>0,"EXCEPTIONS SECTION INCOMPLETE",IF(B4>0,"EXCEPTION/S APPLY - NO CIA REQUIRED",IF(AND(B3=7,B7=5),"NO CIA REQUIRED",IF(AND(B3=7,B8=5),"NO CIA REQUIRED",IF(AND(B3=7,B6>0),"CIA REQUIRED",IF(AND(B3=7,B8>0),"THRESHOLDS SECTION INCOMPLETE"))))))) -> EXCEPTIONS SECTION INCOMPLETE
A4: Exceptions Yes | B4: =COUNTIF('CIA-Screening'!E6:E12,"Yes") -> 0 | D4: Result - Thresholds Table
A5: Exceptions blanks | B5: =COUNTIF('CIA-Screening'!E6:E12,"") -> 7 | D5: =IF(FORMULAS!B4>0,"EXCEPTION/S APPLY - NO CIA REQUIRED",IF(FORMULAS!B8>0,"THRESHOLDS SECTION INCOMPLETE",IF(FORMULAS!B5>0,"EXCEPTIONS SECTION INCOMPLETE",IF(FORMULAS!B6>0,"CIA REQUIRED",IF(FORMULAS!B8>0,"THRESHOLD SECTION INCOMPLETE",IF(AND(FORMULAS!B7=4,FORMULAS!B8=0),"NO CIA REQUIRED")))))) -> THRESHOLDS SECTION INCOMPLETE | E5: =IF(FORMULAS!B4>0,"EXCEPTION/S APPLY - NO CIA REQUIRED",IF(FORMULAS!B8>0,"Screening questions incomplete",IF(FORMULAS!B5>0,"Screening questions incomplete",IF(FORMULAS!B6>0,"CIA REQUIRED",IF(FORMULAS!B8>0,"SCREENING INCOMPLETE",IF(AND(FORMULAS!B7=4,FORMULAS!B8=0),"NO CIA REQUIRED")))))) -> Screening questions incomplete
A6: Threshold Yes | B6: =COUNTIF('CIA-Screening'!E18:E21,"Yes") -> 0
A7: Threshold No | B7: =COUNTIF('CIA-Screening'!E18:E21,"No") -> 0
A8: Threshold blanks | B8: =COUNTIF('CIA-Screening'!E18:E21,"") -> 4
A11: Scores | B11: 4 to 8 | C11: Significant and/or long term positive impacts identified
B12: 1 to 3 | C12: Slight and/or short term positive impacts identified
B13: 0 | C13: Not applicable/No Impact
B14: Minus 1 to minus 3 | C14: Slight and/or short term positive impacts identified
B15: Minus 4 to minus 8 | C15: Significant and/or long term positive impacts identified
A17: Reviewer Next Step
A18: Env Blanks | B18: =COUNTIF('Summary Report'!F22:F31,"") -> 10 | C18: Total blanks
A19: Social Blanks | B19: =COUNTIF('Summary Report'!F33:F43,"") -> 11 | C19: =B18+B19 -> 21
A20: Env Queries | B20: =COUNTIF('Summary Report'!F22:F31,"Queried") -> 0 | C20: Total queries
A21: Social Queries | B21: =COUNTIF('Summary Report'!F33:F43,"Queried") -> 0 | C21: =B20+B21 -> 0
A22: Env Rejects | B22: =COUNTIF('Summary Report'!F22:F31,"Rejected") -> 0 | C22: Total rejects
A23: Social Rejects | B23: =COUNTIF('Summary Report'!F33:F43,"Rejected") -> 0 | C23: =B22+B23 -> 0
A24: Env Accepts | B24: =COUNTIF('Summary Report'!F22:F31,"Accepted") -> 0 | C24: Total accepts
A25: Social Accepts | B25: =COUNTIF('Summary Report'!F33:F43,"Accepted") -> 0 | C25: =B24+B25 -> 0
B26: Outcome: | C26: =IF(C19>0,"REVIEW INCOMPLETE",IF(C21>0,"ITEMS QUERIED/REJECTED - RETURN TO OFFICER",IF(C23>0,"ITEMS QUERIED/REJECTED - RETURN TO OFFICER",IF(C25=21,"REVIEW COMPLETE - READY TO PASS TO DECISION MAKER/S")))) -> REVIEW INCOMPLETE

Sheet Dashboard
B4: Climate Impact Assessment
M5: KEY | N5: IMPACTS | R5: ACTION
N6: Significant and/or long-term positive impact identified. | R6: No changes needed.
N10: Slight or short-term positive impact identified. | R10: No changes needed but could be reviewed to improve.
N14: Not applicable or no cause for concern. | R14: No changes needed.
N18: Slight or short-term negative impact identified. Review to identify possible improvements. | R18: Review to identify possible improvements.
N22: Significant and/or long-term negative impact identified. | R22: Changes needed before proceeding. If changes are not possible, justification required.
N26: Responses incomplete. | R26: Please return to assessment and answer all of the questions in this section.
B35: Equality Impact Assessment | G35: =FORMULAS!#REF! -> #REF!
B36: Data Protection Impact Assessment | G36: =FORMULAS!#REF! -> #REF!

Sheet Summary Report
B2: CIA - SUMMARY REPORT | E2: Version: 15 April 2025
B3: Guidance - how to use and complete this page (hover cursor over this cell)
B5: Name of proposal | D5: =Details!C4 -> 0
B6: Type | D6: =Details!C7 -> 0
B7: Department/public body | D7: =Details!C13 -> 0
B8: Section/division/team/ directorate | D8: =Details!C16 -> 0
B9: Name of officer/person completing assessment | D9: =Details!C19 -> 0
B10: Date | D10: =Details!C24 -> 0
B11: Aims, objectives, anticipated outcomes | D11: =Details!C27 -> 0
B12: Responsible for implementing/delivering the proposal | D12: =Details!C30 -> 0
C14: SCREENING RESULTS | E14: FULL ASSESSMENT
B15: CLIMATE IMPACT | C15: =FORMULAS!E5 -> Screening questions incomplete | E15: If a CIA has been completed, the impact wheel and results table will be populated. Even if a CIA is not required, if one has been completed, it must be taken into account.
B16: DISCRETION Where a CIA is required, but has not been completed, you must record the reason why. | E16: ='CIA-Screening'!C29 -> 0
B19: CLIMATE IMPACT ASSESSMENT: RESULTS TABLE | I19: NOTES FOR THE REVIEWER
E20: Name of Reviewer: | G20: >>ENTER REVIEWER NAME HERE<<
B21: ENVIRONMENTAL | C21: Scores | D21: Action | E21: Justification/Mitigation/Explanation | F21: Reviewed | G21: Reviewer comments | I21: The Reviewer is the person who would normally check your papers/bundle of documents before it is submitted to the Decision Maker/s. This is usually a manager. The Reviewer should check that they are satisfied with the content of the Summary Report (this) page. Check that the scoring and justifications/explanations appear reasonable and comprehensive. Consider whether mitigations have been included or, if not, it has been explained why they are not possible/appropriate. If you are content, select 'Accepted' in the 'Reviewed' column. If not, select 'Rejected' or 'Queried' in the 'Reviewed' column and return the assessment to the responsible officer to update. The assessment should not be submitted to the Decision Maker until all criteria are marked 'Accepted' by the Reviewer.
B22: GHGs | C22: =IF('Env Wheel'!I3=20,0,'Env Wheel'!I3) -> 0 | D22: =IF(C22=0, "No action required.",IF(C22>0,"No action required",IF(C22<-3, "If changes are not possible, justification required. Include details of mitigations, if any.",IF(C22<0>-4,"If changes are not possible, justification required. Include details of mitigations, if any.","")))) -> No action required. | E22: ='CIA-Environment'!C44 -> 0
B23: Air Quality | C23: =IF('Env Wheel'!I4=20,0,'Env Wheel'!I4) -> 0 | D23: =IF(C23=0, "No action required.",IF(C23>0,"No action required",IF(C23<-3, "If changes are not possible, justification required. Include details of mitigations, if any.",IF(C23<0>-4,"If changes are not possible, justification required. Include details of mitigations, if any.","")))) -> No action required. | E23: ='CIA-Environment'!C61 -> 0
B24: Sustainable Transport | C24: =IF('Env Wheel'!I5=20,0,'Env Wheel'!I5) -> 0 | D24: =IF(C24=0, "No action required.",IF(C24>0,"No action required",IF(C24<-3, "If changes are not possible, justification required. Include details of mitigations, if any.",IF(C24<0>-4,"If changes are not possible, justification required. Include details of mitigations, if any.","")))) -> No action required. | E24: ='CIA-Environment'!C78 -> 0
B25: Land Use Change | C25: =IF('Env Wheel'!I6=20,0,'Env Wheel'!I6) -> 0 | D25: =IF(C25=0, "No action required.",IF(C25>0,"No action required",IF(C25<-3, "If changes are not possible, justification required. Include details of mitigations, if any.",IF(C25<0>-4,"If changes are not possible, justification required. Include details of mitigations, if any.","")))) -> No action required. | E25: ='CIA-Environment'!C95 -> 0
B26: Biodiversity | C26: =IF('Env Wheel'!I7=20,0,'Env Wheel'!I7) -> 0 | D26: =IF(C26=0, "No action required.",IF(C26>0,"No action required",IF(C26<-3, "If changes are not possible, justification required. Include details of mitigations, if any.",IF(C26<0>-4,"If changes are not possible, justification required. Include details of mitigations, if any.","")))) -> No action required. | E26: ='CIA-Environment'!C112 -> 0
B27: Soil, Watercourse and Marine Health | C27: =IF('Env Wheel'!I8=20,0,'Env Wheel'!I8) -> 0 | D27: =IF(C27=0, "No action required.",IF(C27>0,"No action required",IF(C27<-3, "If changes are not possible, justification required. Include details of mitigations, if any.",IF(C27<0>-4,"If changes are not possible, justification required. Include details of mitigations, if any.","")))) -> No action required. | E27: ='CIA-Environment'!C129 -> 0
B28: Climate Change Adaptation | C28: =IF('Env Wheel'!I9=20,0,'Env Wheel'!I9) -> 0 | D28: =IF(C28=0, "No action required.",IF(C28>0,"No action required",IF(C28<-3, "If changes are not possible, justification required. Include details of mitigations, if any.",IF(C28<0>-4,"If changes are not possible, justification required. Include details of mitigations, if any.","")))) -> No action required. | E28: ='CIA-Environment'!C146 -> 0
B29: Energy Use | C29: =IF('Env Wheel'!I10=20,0,'Env Wheel'!I10) -> 0 | D29: =IF(C29=0, "No action required.",IF(C29>0,"No action required",IF(C29<-3, "If changes are not possible, justification required. Include details of mitigations, if any.",IF(C29<0>-4,"If changes are not possible, justification required. Include details of mitigations, if any.","")))) -> No action required. | E29: ='CIA-Environment'!C163 -> 0
B30: Sustainable Materials | C30: =IF('Env Wheel'!I11=20,0,'Env Wheel'!I11) -> 0 | D30: =IF(C30=0, "No action required.",IF(C30>0,"No action required",IF(C30<-3, "If changes are not possible, justification required. Include details of mitigations, if any.",IF(C30<0>-4,"If changes are not possible, justification required. Include details of mitigations, if any.","")))) -> No action required. | E30: ='CIA-Environment'!C180 -> 0
B31: Waste | C31: =IF('Env Wheel'!I12=20,0,'Env Wheel'!I12) -> 0 | D31: =IF(C31=0, "No action required.",IF(C31>0,"No action required",IF(C31<-3, "If changes are not possible, justification required. Include details of mitigations, if any.",IF(C31<0>-4,"If changes are not possible, justification required. Include details of mitigations, if any.","")))) -> No action required. | E31: ='CIA-Environment'!C197 -> 0
B32: SOCIAL | C32: Scores | D32: Action | E32: Justification/Explanation | F32: Reviewed | G32: Reviewer comments | I32: NOTES FOR DECISION MAKER/S
B33: Food | C33: =IF('Social Wheel'!I3=20,0,'Social Wheel'!I3) -> 0 | D33: =IF(C33=0, "No action required.",IF(C33>0,"No action required",IF(C33<-3, "If changes are not possible, justification required. Include details of mitigations, if any.",IF(C33<0>-4,"If changes are not possible, justification required. Include details of mitigations, if any.","")))) -> No action required. | E33: ='CIA-Social'!C18 -> 0 | I33: It is part of your legal responsibilities to ensure that the public body, on behalf of which you are making this decision, in performing its duties, acts in the way that it considers best to contribute to the climate change duties, which are: • meeting our statutory emissions reduction targets • supporting a just transition and climate justice • supporting sustainable development and the UN SDGs • protecting and enhancing biodiversity, ecosystems and ecosystem services. It is also part of your legal responsibilities, when making a decision, to take a Climate Impact Assessment into account, if one has been prepared. Refer to the Impact Wheel for an 'at a glance' summary of the expected impacts of this proposal. For more detail about how/why each criteria has received these scores, see the 'Justification/Explanation' column in the Results Table to the right. You should be satisfied that the proposal presented represents the best way contribute to the climate change goals while achieving the goals of the proposal. If you are not satisfied - for example, if you believe changes or additional/alternative mitigations are possible, you should request that these be included in the proposal. The Climate Impact Assessment does not force any particular decision - where you feel it necessary to proceed despite negative impacts, you should ensure that you are satisfied that the justifications for doing so are explained and are sufficient.
B34: Health | C34: =IF('Social Wheel'!I4=20,0,'Social Wheel'!I4) -> 0 | D34: =IF(C34=0, "No action required.",IF(C34>0,"No action required",IF(C34<-3, "If changes are not possible, justification required. Include details of mitigations, if any.",IF(C34<0>-4,"If changes are not possible, justification required. Include details of mitigations, if any.","")))) -> No action required. | E34: ='CIA-Social'!C35 -> 0
B35: Housing | C35: =IF('Social Wheel'!I5=20,0,'Social Wheel'!I5) -> 0 | D35: =IF(C35=0, "No action required.",IF(C35>0,"No action required",IF(C35<-3, "If changes are not possible, justification required. Include details of mitigations, if any.",IF(C35<0>-4,"If changes are not possible, justification required. Include details of mitigations, if any.","")))) -> No action required. | E35: ='CIA-Social'!C52 -> 0
B36: Education | C36: =IF('Social Wheel'!I6=20,0,'Social Wheel'!I6) -> 0 | D36: =IF(C36=0, "No action required.",IF(C36>0,"No action required",IF(C36<-3, "If changes are not possible, justification required. Include details of mitigations, if any.",IF(C36<0>-4,"If changes are not possible, justification required. Include details of mitigations, if any.","")))) -> No action required. | E36: ='CIA-Social'!C69 -> 0
B37: Community | C37: =IF('Social Wheel'!I7=20,0,'Social Wheel'!I7) -> 0 | D37: =IF(C37=0, "No action required.",IF(C37>0,"No action required",IF(C37<-3, "If changes are not possible, justification required. Include details of mitigations, if any.",IF(C37<0>-4,"If changes are not possible, justification required. Include details of mitigations, if any.","")))) -> No action required. | E37: ='CIA-Social'!C86 -> 0
B38: Culture | C38: =IF('Social Wheel'!I8=20,0,'Social Wheel'!I8) -> 0 | D38: =IF(C38=0, "No action required.",IF(C38>0,"No action required",IF(C38<-3, "If changes are not possible, justification required. Include details of mitigations, if any.",IF(C38<0>-4,"If changes are not possible, justification required. Include details of mitigations, if any.","")))) -> No action required. | E38: ='CIA-Social'!C103 -> 0
B39: Accessibility | C39: =IF('Social Wheel'!I9=20,0,'Social Wheel'!I9) -> 0 | D39: =IF(C39=0, "No action required.",IF(C39>0,"No action required",IF(C39<-3, "If changes are not possible, justification required. Include details of mitigations, if any.",IF(C39<0>-4,"If changes are not possible, justification required. Include details of mitigations, if any.","")))) -> No action required. | E39: ='CIA-Social'!C120 -> 0
B40: Local Economy and Jobs | C40: =IF('Social Wheel'!I10=20,0,'Social Wheel'!I10) -> 0 | D40: =IF(C40=0, "No action required.",IF(C40>0,"No action required",IF(C40<-3, "If changes are not possible, justification required. Include details of mitigations, if any.",IF(C40<0>-4,"If changes are not possible, justification required. Include details of mitigations, if any.","")))) -> No action required. | E40: ='CIA-Social'!C137 -> 0
B41: Safety | C41: =IF('Social Wheel'!I11=20,0,'Social Wheel'!I11) -> 0 | D41: =IF(C41=0, "No action required.",IF(C41>0,"No action required",IF(C41<-3, "If changes are not possible, justification required. Include details of mitigations, if any.",IF(C41<0>-4,"If changes are not possible, justification required. Include details of mitigations, if any.","")))) -> No action required. | E41: ='CIA-Social'!C154 -> 0
B42: Democratic Voice | C42: =IF('Social Wheel'!I12=20,0,'Social Wheel'!I12) -> 0 | D42: =IF(C42=0, "No action required.",IF(C42>0,"No action required",IF(C42<-3, "If changes are not possible, justification required. Include details of mitigations, if any.",IF(C42<0>-4,"If changes are not possible, justification required. Include details of mitigations, if any.","")))) -> No action required. | E42: ='CIA-Social'!C188 -> 0
B43: Equity | C43: =IF('Social Wheel'!I13=20,0,'Social Wheel'!I13) -> 0 | D43: =IF(C43=0, "No action required.",IF(C43>0,"No action required",IF(C43<-3, "If changes are not possible, justification required. Include details of mitigations, if any.",IF(C43<0>-4,"If changes are not possible, justification required. Include details of mitigations, if any.","")))) -> No action required. | E43: ='CIA-Social'!C171 -> 0
F44: RESULT OF RFEVIEW: | G44: =FORMULAS!C26 -> REVIEW INCOMPLETE
B47: INFORMATION ABOUT PRINTING This information is not included in the print area, so will not appear on the printed document. When you are ready to submit to the Decision Maker, print this page as a PDF. It should automatically fit on a single A3 sheet. If your justifications/explanations are lengthy, it may reduce the size of the text when printed - if this occurs and you want to change it go to File -> Print -> Settings -> Bottom button, change from 'Fit sheet on one page' to 'Fit all columns on one page'.
...

Sheet Guidance
B1: GUIDANCE - FULL WORDING
B2: ENVIRONMENTAL
C3: JUMP TO GUIDANCE - CLICK LINK Ü
B4: 1 | C4: Greenhouse Gases
B5: 2 | C5: Air Quality
B6: 3 | C6: Sustainable Transport
B7: 4 | C7: Land Use Change
B8: 5 | C8: Biodiversity
B9: 6 | C9: Soil, Watercourse and Marine Health
B10: 7 | C10: Climate Change Adaptation
B11: 8 | C11: Energy Use
B12: 9 | C12: Sustainable Materials
B13: 10 | C13: Waste
B14: SOCIAL
C15: JUMP TO GUIDANCE - CLICK LINK Ü
B16: 1 | C16: Food
B17: 2 | C17: Health and Wellbeing
B18: 3 | C18: Housing
B19: 4 | C19: Education
B20: 5 | C20: Built Community
B21: 6 | C21: Cultural Community
B22: 7 | C22: Accessibility
B23: 8 | C23: Local Economy and Jobs
B24: 9 | C24: Safety and Crime
B25: 10 | C25: Equity
B26: 11 | C26: Democratic Voice
B29: 1 | C29: Greenhouse Gases
C30: Why is this important?
C31: GHGs are causing climate change which presents many significant risks to life, livelihoods, health and wellbeing. Public bodies have a legal obligation to contribute toward meeting national emissions reduction targets Climate Change Act 2021, Section 21(a) and (b)
C32: Not sure?
C33: The greenhouse gases are: (a) carbon dioxide, primarily released when fossil fuels (coal, gas, oil) are burnt (b) methane, primarily released by livestock and waste processes (c) nitrous oxide, primarily from fertilisers (d) hydrofluorocarbons, perfluorocarbons, sulphur hexafluoride and nitrogen trifluoride, produced by refrigeration and air-conditioning processes. High levels of these gases have led to the greenhouse effect, causing average temperatures to rise and the climate to change.
C34: Some examples of proposals likely to reduce GHG emissions: • Policies that make low carbon choices easier or cheaper • Improving insulation in buildings • Replacing gas/oil boilers with air-source heat pumps • Reducing the amount of waste produced • Encouraging public transport, walking, cycling • Reducing use of petrol or diesel vehicles | D34: Some examples of proposals likely to increase GHG emissions: • Policies that make low carbon choices more difficult or expensive • Construction • Relocation of a service (if further away from users) • Increases in digital storage needs • Increase in energy use • Replacing grassland/woodland with agriculture or settlement
C35: Possible mitigations: Low carbon technology, route planning, energy efficiencies, targeted support schemes.
C36: Get more help
C37: Access the CIA User Guide and lots of other climate change resources by visiting netzero.im/publicbodies or contact publicbodiesclimate@gov.im
B38: >>>>> JUMP BACK TO TOP - CLICK HERE <<<<<
B39: 2 | C39: Air Quality
C40: Why is this important?
C41: Air quality is important for public health. It significantly impacts people's lives and lifespans. Reducing pollution to improve air quality can save lives, protect our NHS, and improve our communities. Some air pollutants are also GHGs.
C42: Not sure?
...

Sheet Drop downs
A1: Statement | B1: Score
A2: Significant increase | B2: 2 | G2: Long-term | L2: Accepted | O2: Overarching programme or strategy
A3: Slight increase | B3: 1 | G3: Short-term | L3: Queried | O3: Policy
A4: No change or n/a | B4: 0 | L4: Rejected | O4: Legislation
A5: Slight decrease | B5: -1 | O5: Project
A6: Significant decrease | B6: -2 | O6: Event
G7: Yes | I7: Yes - slightly | L7: No further action needed | O7: Other Decision
A8: Significant involvement | B8: 2 | G8: No | I8: Yes - significantly | L8: Recommendation applied
A9: Some involvement | B9: 1 | G9: N/A | I9: No | L9: Recommendation not applied
A10: N/A | B10: 0
A11: No involvement | B11: -2
A13: SOCIAL | I13: ENVIRONMENTAL
A14: Food | I14: Air Quality | N14: GHGs
A15: Significantly promote healthy and/or affordable food | I15: Significantly decrease air pollutants | N15: Significantly reduce GHG emissions (or significantly increase removals)
A16: Slightly promote healthy and/or affordable food | I16: Slightly decrease air pollutants | N16: Slightly reduce GHG emissions (or slightly increase removals)
A17: Not applicable/No Impact | I17: Not applicable/No Impact | N17: Not applicable/No Impact
A18: Slightly impede healthy and/or affordable food | I18: Slightly increase air pollutants | N18: Slightly increase GHG emissions (or slightly reduce removals)
A19: Significantly impede healthy and/or affordable food | I19: Significantly increase air pollutants | N19: Significantly increase GHG emissions (or signficiantly reduce removals)
A21: Health | I21: Sustainable Transport
A22: Significantly increase positive health outcomes | I22: Significantly encourage the use of sustainable transport
A23: Slightly increase positive health outcomes | I23: Slightly encourage the use of sustainable transport
A24: Not applicable/No Impact | I24: Not applicable/No Impact
A25: Slightly decrease positive health outcomes | I25: Slightly discourage the use of sustainable transport
A26: Significantly decrease positive health outcomes | I26: Significantly discourage the use of sustainable transport
A28: Housing | I28: Land Use Change
A29: Significantly increase the number of or access to quality and/or affordable homes | I29: Significant change to land use that increases positive impacts
A30: Slightly increase the number of or access to quality and/or affordable homes | I30: Slight change to land use that increases positive impacts
A31: Not applicable/No Impact | I31: Not applicable/No Impact
A32: Slightly decrease the number of or access to quality and/or affordable homes | I32: Slight change to land use that increases negative impacts
A33: Significantly decrease the number of or access to quality and/or affordable homes | I33: Significant change to land use that increases negative impacts
... A54: Significantly reduce social or cultural resources or support | I54: Significantly decrease adaptation
A56: Accessibility | I56: Energy Use | M56: Renewables
A57: Actively reduces barriers to increase access | I57: Significantly decrease energy use | M57: Fossil fuels
A58: Presents no barriers to access | I58: Slightly decrease energy use | M58: Renewables
A59: Not applicable/No Impact | I59: Not applicable/No Impact | M59: Both
A60: Risk of some barriers to access | I60: Slightly increase energy use
A61: Presents barriers to access in one or more areas | I61: Significantly increase energy use
A63: Local economy and employment | I63: Sustainable Materials
A64: Significant support for the local economy and/or employment | I64: Sustainable resources used throughout
A65: Slight support for the local economy and/or employment | I65: Sustainable resources used in most places
...
